Workbook

Sheet Summary
A1: Business Sales Performance — Key Metrics
A2: Maincrafts Technology | Business Analytics (Excel + Power BI) — Task 1 | FY2024
A4: TOTAL REVENUE | C4: TOTAL PROFIT | E4: OVERALL MARGIN | G4: TOTAL ORDERS
A5: =Pivot_Sales_by_Region!B9 -> 58013327 | C5: =Pivot_Sales_by_Region!C9 -> 9068027 | E5: =Pivot_Sales_by_Region!E9 -> 0.15630938 | G5: =Pivot_Sales_by_Region!D9 -> 900
A8: Best Performing Region: | C8: =INDEX(Pivot_Sales_by_Region!A4:A8,MATCH(MAX(Pivot_Sales_by_Region!B4:B8),Pivot_Sales_by_Region!B4:B8,0)) -> North
A9: Top Product by Revenue: | C9: =Pivot_Sales_by_Product!A4 -> Laptop
A10: Weakest Region: | C10: =INDEX(Pivot_Sales_by_Region!A4:A8,MATCH(MIN(Pivot_Sales_by_Region!B4:B8),Pivot_Sales_by_Region!B4:B8,0)) -> South
A30: Figures pull live from the Pivot_Sales_by_Region and Pivot_Sales_by_Product sheets — update Cleaned_Data and every number here recalculates.

Sheet Raw_Data
A1: Order_ID | B1: Order_Date | C1: Region | D1: Product | E1: Category | F1: Sales_Amount | G1: Profit | H1: Quantity
A2: ORD1344 | B2: 45332 | C2: East | D2: Office Chair | E2: Furniture | F2: 67464 | G2: 9175.1 | H2: 9
A3: ORD1170 | B3: 45614 | C3: Central | D3: Formal Shirt | E3: Clothing | F3: 8212 | G3: 1494.58 | H3: 4
A4: ORD1890 | B4: 45381 | C4: West | D4: Mixer Grinder | E4: Appliances | F4: 13152 | G4: 1407.26 | H4: 2
A5: ORD1059 | B5: 45626 | C5: Central | D5: Laptop | E5: Electronics | F5: 491580 | G5: 85043.34 | H5: 9
A6: ORD1668 | B6: 45556 | C6: Central | D6: T-Shirt | E6: Clothing | F6: 6010 | G6: 1045.74 | H6: 10
A7: ORD1476 | B7: 45596 | C7: West | D7: Sneakers | E7: Clothing | F7: 10452 | G7: 2895.2 | H7: 6
A8: ORD1680 | B8: 45429 | C8: East | D8: Laptop | E8: Electronics | F8: 531408 | G8: 84493.87 | H8: 6
A9: ORD1840 | B9: 45312 | C9: South | D9: Sneakers | E9: Clothing | F9: 27184 | G9: 4430.99 | H9: 8
A10: ORD1522 | B10: 45452 | C10: North | D10: Study Table | E10: Furniture | F10: 29580 | G10: 4259.52 | H10: 5
A11: ORD1288 | B11: 45484 | C11: South | D11: Bluetooth Speaker | E11: Electronics | F11: 6768 | G11: 1028.74 | H11: 3
A12: ORD1630 | B12: 45580 | C12: South | D12: Air Fryer | E12: Appliances | F12: 46256 | G12: 7123.42 | H12: 4
A13: ORD1549 | B13: 45540 | C13: East | D13: T-Shirt | E13: Clothing | F13: 394 | G13: 66.98 | H13: 1
... A57: ORD1379 | B57: 45548 | C57: Central | D57: File Folder | E57: Stationery | F57: 115 | G57: 26.22 | H57: 1
A58: ORD1381 | B58: 45380 | C58: West | D58: Microwave Oven | E58: Appliances | F58: 83700 | H58: 6
A59: ORD1002 | B59: 45344 | C59: Central | D59: Tablet | E59: Electronics | F59: 396510 | G59: 32910.33 | H59: 10
A60: ORD1349 | B60: 45619 | C60: North | D60: File Folder | E60: Stationery | F60: 558 | G60: 183.02 | H60: 9
A61: ORD1567 | B61: 45414 | C61: West | D61: Pen Set | E61: Stationery | F61: 346 | G61: 103.8 | H61: 2
A62: ORD1466 | B62: 45624 | C62: North | D62: Tablet | E62: Electronics | F62: 257985 | G62: 30442.23 | H62: 7
A63: ORD1783 | B63: 45396 | C63: Central | D63: Smartphone | E63: Electronics | F63: 237966 | H63: 6
A64: ORD1608 | B64: 45317 | C64: East | D64: Bookshelf | E64: Furniture | F64: 9027 | G64: 2202.59 | H64: 3
A65: ORD1758 | B65: 45546 | C65: North | D65: Headphones | E65: Electronics | F65: 29239 | G65: 2456.08 | H65: 7
A66: ORD1169 | B66: 45439 | C66: West | D66: Jeans | E66: Clothing | F66: 10376 | G66: 1618.66 | H66: 8
A67: ORD1764 | B67: 45441 | C67: Central | D67: Mixer Grinder | E67: Appliances | F67: 17220 | G67: 1808.1 | H67: 6
A68: ORD1677 | B68: 45540 | C68: Central | D68: Water Purifier | E68: Appliances | F68: 52904 | G68: 6189.77 | H68: 8
A69: ORD1174 | B69: 45533 | C69: South | D69: Highlighters | E69: Stationery | F69: 693 | G69: 191.96 | H69: 9
A70: ORD1519 | B70: 45426 | C70: West | D70: Mixer Grinder | E70: Appliances | F70: 41340 | G70: 5746.26 | H70: 6
A71: ORD1742 | B71: 45610 | C71: East | D71: Jacket | E71: Clothing | F71: 5452 | G71: 1706.48 | H71: 2
A72: ORD1811 | B72: 45513 | C72: East | D72: Laptop | E72: Electronics | F72: 553875 | G72: 50956.5 | H72: 7
A73: ORD1263 | B73: 45497 | C73: Central | D73: Tablet | E73: Electronics | F73: 226338 | G73: 35082.39 | H73: 7
A74: ORD1101 | B74: 45370 | C74: South | D74: Tablet | E74: Electronics | F74: 270984 | G74: 30621.19 | H74: 7
A75: ORD1084 | B75: 45486 | C75: South | D75: Water Purifier | E75: Appliances | F75: 109300 | G75: 15411.3 | H75: 10
... A110: ORD1814 | B110: 45446 | C110: Central | D110: Tablet | E110: Electronics | F110: 203415 | G110: 24002.97 | H110: 5
A111: ORD1515 | B111: 45387 | C111: West | D111: Pen Set | E111: Stationery | F111: 364 | H111: 1
A112: ORD1484 | B112: 45473 | C112: Central | D112: Tablet | E112: Electronics | F112: 332610 | G112: 55213.26 | H112: 10
A113: ORD1401 | B113: 45443 | C113: Central | D113: T-Shirt | E113: Clothing | F113: 2636 | G113: 716.99 | H113: 4
A114: ORD1809 | B114: 45319 | C114: South | D114: Formal Shirt | E114: Clothing | F114: 8710 | G114: 1428.44 | H114: 5
A115: ORD1455 | B115: 45569 | C115: North | D115: Mixer Grinder | E115: Appliances | F115: 2608 | G115: 508.56 | H115: 1
A116: ORD1878 | B116: 45617 | C116: North | D116: Formal Shirt | E116: Clothing | F116: 4572 | G116: 818.39 | H116: 2
A117: ORD1065 | B117: 45574 | C117: West | D117: Microwave Oven | E117: Appliances | F117: 6832 | G117: 737.86 | H117: 1
...

Sheet Cleaned_Data
A1: Order ID | B1: Order Date | C1: Region | D1: Product | E1: Category | F1: Sales Amount | G1: Profit | H1: Quantity | I1: Total Sales | J1: Profit Margin | K1: Month Num
A2: ORD1344 | B2: 45332 | C2: East | D2: Office Chair | E2: Furniture | F2: 67464 | G2: 9175.1 | H2: 9 | I2: =F2 -> 67464 | J2: =IFERROR(G2/F2,0) -> 0.13599994 | K2: =MONTH(B2) -> 2
A3: ORD1170 | B3: 45614 | C3: Central | D3: Formal Shirt | E3: Clothing | F3: 8212 | G3: 1494.58 | H3: 4 | I3: =F3 -> 8212 | J3: =IFERROR(G3/F3,0) -> 0.18199951 | K3: =MONTH(B3) -> 11
A4: ORD1890 | B4: 45381 | C4: West | D4: Mixer Grinder | E4: Appliances | F4: 13152 | G4: 1407.26 | H4: 2 | I4: =F4 -> 13152 | J4: =IFERROR(G4/F4,0) -> 0.1069997 | K4: =MONTH(B4) -> 3
A5: ORD1059 | B5: 45626 | C5: Central | D5: Laptop | E5: Electronics | F5: 491580 | G5: 85043.34 | H5: 9 | I5: =F5 -> 491580 | J5: =IFERROR(G5/F5,0) -> 0.173 | K5: =MONTH(B5) -> 11
A6: ORD1668 | B6: 45556 | C6: Central | D6: T-Shirt | E6: Clothing | F6: 6010 | G6: 1045.74 | H6: 10 | I6: =F6 -> 6010 | J6: =IFERROR(G6/F6,0) -> 0.174 | K6: =MONTH(B6) -> 9
A7: ORD1476 | B7: 45596 | C7: West | D7: Sneakers | E7: Clothing | F7: 10452 | G7: 2895.2 | H7: 6 | I7: =F7 -> 10452 | J7: =IFERROR(G7/F7,0) -> 0.27699962 | K7: =MONTH(B7) -> 10
A8: ORD1680 | B8: 45429 | C8: East | D8: Laptop | E8: Electronics | F8: 531408 | G8: 84493.87 | H8: 6 | I8: =F8 -> 531408 | J8: =IFERROR(G8/F8,0) -> 0.159 | K8: =MONTH(B8) -> 5
A9: ORD1840 | B9: 45312 | C9: South | D9: Sneakers | E9: Clothing | F9: 27184 | G9: 4430.99 | H9: 8 | I9: =F9 -> 27184 | J9: =IFERROR(G9/F9,0) -> 0.16299993 | K9: =MONTH(B9) -> 1
A10: ORD1522 | B10: 45452 | C10: North | D10: Study Table | E10: Furniture | F10: 29580 | G10: 4259.52 | H10: 5 | I10: =F10 -> 29580 | J10: =IFERROR(G10/F10,0) -> 0.144 | K10: =MONTH(B10) -> 6
A11: ORD1288 | B11: 45484 | C11: South | D11: Bluetooth Speaker | E11: Electronics | F11: 6768 | G11: 1028.74 | H11: 3 | I11: =F11 -> 6768 | J11: =IFERROR(G11/F11,0) -> 0.15200059 | K11: =MONTH(B11) -> 7
A12: ORD1630 | B12: 45580 | C12: South | D12: Air Fryer | E12: Appliances | F12: 46256 | G12: 7123.42 | H12: 4 | I12: =F12 -> 46256 | J12: =IFERROR(G12/F12,0) -> 0.15399991 | K12: =MONTH(B12) -> 10
A13: ORD1549 | B13: 45540 | C13: East | D13: T-Shirt | E13: Clothing | F13: 394 | G13: 66.98 | H13: 1 | I13: =F13 -> 394 | J13: =IFERROR(G13/F13,0) -> 0.17 | K13: =MONTH(B13) -> 9
... A901: ORD1404 | B901: 45419 | C901: North | D901: Bookshelf | E901: Furniture | F901: 44506 | G901: 7922.07 | H901: 7 | I901: =F901 -> 44506 | J901: =IFERROR(G901/F901,0) -> 0.17800004 | K901: =MONTH(B901) -> 5
A903: Total Sales = Sales Amount (per-order total). Profit Margin = Profit / Sales Amount. Month Num is a helper column used by the pivot tables on the next sheets.

Sheet Pivot_Sales_by_Region
A1: PIVOT TABLE — Sales by Region
A3: Region | B3: Total Sales | C3: Total Profit | D3: Order Count | E3: Profit Margin
A4: Central | B4: =SUMIFS(Cleaned_Data!F$2:F$901,Cleaned_Data!C$2:C$901,A4) -> 12036654 | C4: =SUMIFS(Cleaned_Data!G$2:G$901,Cleaned_Data!C$2:C$901,A4) -> 1933759.7 | D4: =COUNTIFS(Cleaned_Data!C$2:C$901,A4) -> 168 | E4: =IFERROR(C4/B4,0) -> 0.16065592
A5: East | B5: =SUMIFS(Cleaned_Data!F$2:F$901,Cleaned_Data!C$2:C$901,A5) -> 12844629 | C5: =SUMIFS(Cleaned_Data!G$2:G$901,Cleaned_Data!C$2:C$901,A5) -> 1956959.1 | D5: =COUNTIFS(Cleaned_Data!C$2:C$901,A5) -> 185 | E5: =IFERROR(C5/B5,0) -> 0.15235622
A6: North | B6: =SUMIFS(Cleaned_Data!F$2:F$901,Cleaned_Data!C$2:C$901,A6) -> 13271189 | C6: =SUMIFS(Cleaned_Data!G$2:G$901,Cleaned_Data!C$2:C$901,A6) -> 2068968.1 | D6: =COUNTIFS(Cleaned_Data!C$2:C$901,A6) -> 186 | E6: =IFERROR(C6/B6,0) -> 0.15589923
A7: South | B7: =SUMIFS(Cleaned_Data!F$2:F$901,Cleaned_Data!C$2:C$901,A7) -> 9400399 | C7: =SUMIFS(Cleaned_Data!G$2:G$901,Cleaned_Data!C$2:C$901,A7) -> 1529336.4 | D7: =COUNTIFS(Cleaned_Data!C$2:C$901,A7) -> 181 | E7: =IFERROR(C7/B7,0) -> 0.16268846
A8: West | B8: =SUMIFS(Cleaned_Data!F$2:F$901,Cleaned_Data!C$2:C$901,A8) -> 10460456 | C8: =SUMIFS(Cleaned_Data!G$2:G$901,Cleaned_Data!C$2:C$901,A8) -> 1579003.6 | D8: =COUNTIFS(Cleaned_Data!C$2:C$901,A8) -> 180 | E8: =IFERROR(C8/B8,0) -> 0.15094979
A9: Grand Total | B9: =SUM(B4:B8) -> 58013327 | C9: =SUM(C4:C8) -> 9068027 | D9: =SUM(D4:D8) -> 900 | E9: =IFERROR(C9/B9,0) -> 0.15630938

Sheet Pivot_Sales_by_Product
A1: PIVOT TABLE — Sales by Product
A3: Product | B3: Total Sales | C3: Total Profit | D3: Units Sold | E3: Profit Margin
A4: Laptop | B4: =SUMIFS(Cleaned_Data!F$2:F$901,Cleaned_Data!D$2:D$901,A4) -> 10848853 | C4: =SUMIFS(Cleaned_Data!G$2:G$901,Cleaned_Data!D$2:D$901,A4) -> 1417866.1 | D4: =SUMIFS(Cleaned_Data!H$2:H$901,Cleaned_Data!D$2:D$901,A4) -> 165 | E4: =IFERROR(C4/B4,0) -> 0.13069271
A5: Tablet | B5: =SUMIFS(Cleaned_Data!F$2:F$901,Cleaned_Data!D$2:D$901,A5) -> 8305639 | C5: =SUMIFS(Cleaned_Data!G$2:G$901,Cleaned_Data!D$2:D$901,A5) -> 1017161.1 | D5: =SUMIFS(Cleaned_Data!H$2:H$901,Cleaned_Data!D$2:D$901,A5) -> 286 | E5: =IFERROR(C5/B5,0) -> 0.12246633
A6: Sofa | B6: =SUMIFS(Cleaned_Data!F$2:F$901,Cleaned_Data!D$2:D$901,A6) -> 7663745 | C6: =SUMIFS(Cleaned_Data!G$2:G$901,Cleaned_Data!D$2:D$901,A6) -> 1462289.1 | D6: =SUMIFS(Cleaned_Data!H$2:H$901,Cleaned_Data!D$2:D$901,A6) -> 213 | E6: =IFERROR(C6/B6,0) -> 0.19080607
A7: Smartphone | B7: =SUMIFS(Cleaned_Data!F$2:F$901,Cleaned_Data!D$2:D$901,A7) -> 6920398 | C7: =SUMIFS(Cleaned_Data!G$2:G$901,Cleaned_Data!D$2:D$901,A7) -> 923434.19 | D7: =SUMIFS(Cleaned_Data!H$2:H$901,Cleaned_Data!D$2:D$901,A7) -> 179 | E7: =IFERROR(C7/B7,0) -> 0.13343657
A8: Bed Frame | B8: =SUMIFS(Cleaned_Data!F$2:F$901,Cleaned_Data!D$2:D$901,A8) -> 5382481 | C8: =SUMIFS(Cleaned_Data!G$2:G$901,Cleaned_Data!D$2:D$901,A8) -> 992383.37 | D8: =SUMIFS(Cleaned_Data!H$2:H$901,Cleaned_Data!D$2:D$901,A8) -> 203 | E8: =IFERROR(C8/B8,0) -> 0.18437285
A9: Study Table | B9: =SUMIFS(Cleaned_Data!F$2:F$901,Cleaned_Data!D$2:D$901,A9) -> 2761518 | C9: =SUMIFS(Cleaned_Data!G$2:G$901,Cleaned_Data!D$2:D$901,A9) -> 479120.88 | D9: =SUMIFS(Cleaned_Data!H$2:H$901,Cleaned_Data!D$2:D$901,A9) -> 237 | E9: =IFERROR(C9/B9,0) -> 0.1734991
A10: Water Purifier | B10: =SUMIFS(Cleaned_Data!F$2:F$901,Cleaned_Data!D$2:D$901,A10) -> 2195680 | C10: =SUMIFS(Cleaned_Data!G$2:G$901,Cleaned_Data!D$2:D$901,A10) -> 339044.28 | D10: =SUMIFS(Cleaned_Data!H$2:H$901,Cleaned_Data!D$2:D$901,A10) -> 179 | E10: =IFERROR(C10/B10,0) -> 0.15441425
A11: Office Chair | B11: =SUMIFS(Cleaned_Data!F$2:F$901,Cleaned_Data!D$2:D$901,A11) -> 2163186 | C11: =SUMIFS(Cleaned_Data!G$2:G$901,Cleaned_Data!D$2:D$901,A11) -> 412749.78 | D11: =SUMIFS(Cleaned_Data!H$2:H$901,Cleaned_Data!D$2:D$901,A11) -> 215 | E11: =IFERROR(C11/B11,0) -> 0.19080642
A12: Air Fryer | B12: =SUMIFS(Cleaned_Data!F$2:F$901,Cleaned_Data!D$2:D$901,A12) -> 2112017 | C12: =SUMIFS(Cleaned_Data!G$2:G$901,Cleaned_Data!D$2:D$901,A12) -> 330593.22 | D12: =SUMIFS(Cleaned_Data!H$2:H$901,Cleaned_Data!D$2:D$901,A12) -> 255 | E12: =IFERROR(C12/B12,0) -> 0.15652962
A13: Bookshelf | B13: =SUMIFS(Cleaned_Data!F$2:F$901,Cleaned_Data!D$2:D$901,A13) -> 1772890 | C13: =SUMIFS(Cleaned_Data!G$2:G$901,Cleaned_Data!D$2:D$901,A13) -> 324548.23 | D13: =SUMIFS(Cleaned_Data!H$2:H$901,Cleaned_Data!D$2:D$901,A13) -> 232 | E13: =IFERROR(C13/B13,0) -> 0.18306168
A14: Smartwatch | B14: =SUMIFS(Cleaned_Data!F$2:F$901,Cleaned_Data!D$2:D$901,A14) -> 1602562 | C14: =SUMIFS(Cleaned_Data!G$2:G$901,Cleaned_Data!D$2:D$901,A14) -> 207939.41 | D14: =SUMIFS(Cleaned_Data!H$2:H$901,Cleaned_Data!D$2:D$901,A14) -> 207 | E14: =IFERROR(C14/B14,0) -> 0.12975436
A15: Microwave Oven | B15: =SUMIFS(Cleaned_Data!F$2:F$901,Cleaned_Data!D$2:D$901,A15) -> 1253121 | C15: =SUMIFS(Cleaned_Data!G$2:G$901,Cleaned_Data!D$2:D$901,A15) -> 197112.23 | D15: =SUMIFS(Cleaned_Data!H$2:H$901,Cleaned_Data!D$2:D$901,A15) -> 132 | E15: =IFERROR(C15/B15,0) -> 0.15729704
... A29: File Folder | B29: =SUMIFS(Cleaned_Data!F$2:F$901,Cleaned_Data!D$2:D$901,A29) -> 10994 | C29: =SUMIFS(Cleaned_Data!G$2:G$901,Cleaned_Data!D$2:D$901,A29) -> 3306.61 | D29: =SUMIFS(Cleaned_Data!H$2:H$901,Cleaned_Data!D$2:D$901,A29) -> 134 | E29: =IFERROR(C29/B29,0) -> 0.30076496

Sheet Pivot_Monthly_Trend
A1: PIVOT TABLE — Monthly Sales Trend
A3: Month | B3: Total Sales | C3: Total Profit | D3: Order Count
A4: Jan | B4: =SUMIFS(Cleaned_Data!F$2:F$901,Cleaned_Data!K$2:K$901,1) -> 4634266 | C4: =SUMIFS(Cleaned_Data!G$2:G$901,Cleaned_Data!K$2:K$901,1) -> 845813.87 | D4: =COUNTIFS(Cleaned_Data!K$2:K$901,1) -> 61
A5: Feb | B5: =SUMIFS(Cleaned_Data!F$2:F$901,Cleaned_Data!K$2:K$901,2) -> 5520648 | C5: =SUMIFS(Cleaned_Data!G$2:G$901,Cleaned_Data!K$2:K$901,2) -> 833214.92 | D5: =COUNTIFS(Cleaned_Data!K$2:K$901,2) -> 65
A6: Mar | B6: =SUMIFS(Cleaned_Data!F$2:F$901,Cleaned_Data!K$2:K$901,3) -> 4789980 | C6: =SUMIFS(Cleaned_Data!G$2:G$901,Cleaned_Data!K$2:K$901,3) -> 781796.41 | D6: =COUNTIFS(Cleaned_Data!K$2:K$901,3) -> 71
A7: Apr | B7: =SUMIFS(Cleaned_Data!F$2:F$901,Cleaned_Data!K$2:K$901,4) -> 4749898 | C7: =SUMIFS(Cleaned_Data!G$2:G$901,Cleaned_Data!K$2:K$901,4) -> 773505.56 | D7: =COUNTIFS(Cleaned_Data!K$2:K$901,4) -> 66
A8: May | B8: =SUMIFS(Cleaned_Data!F$2:F$901,Cleaned_Data!K$2:K$901,5) -> 3609800 | C8: =SUMIFS(Cleaned_Data!G$2:G$901,Cleaned_Data!K$2:K$901,5) -> 606474.92 | D8: =COUNTIFS(Cleaned_Data!K$2:K$901,5) -> 74
A9: Jun | B9: =SUMIFS(Cleaned_Data!F$2:F$901,Cleaned_Data!K$2:K$901,6) -> 5070996 | C9: =SUMIFS(Cleaned_Data!G$2:G$901,Cleaned_Data!K$2:K$901,6) -> 763422.33 | D9: =COUNTIFS(Cleaned_Data!K$2:K$901,6) -> 71
A10: Jul | B10: =SUMIFS(Cleaned_Data!F$2:F$901,Cleaned_Data!K$2:K$901,7) -> 4111057 | C10: =SUMIFS(Cleaned_Data!G$2:G$901,Cleaned_Data!K$2:K$901,7) -> 688504.31 | D10: =COUNTIFS(Cleaned_Data!K$2:K$901,7) -> 82
A11: Aug | B11: =SUMIFS(Cleaned_Data!F$2:F$901,Cleaned_Data!K$2:K$901,8) -> 5487151 | C11: =SUMIFS(Cleaned_Data!G$2:G$901,Cleaned_Data!K$2:K$901,8) -> 788091.99 | D11: =COUNTIFS(Cleaned_Data!K$2:K$901,8) -> 77
A12: Sep | B12: =SUMIFS(Cleaned_Data!F$2:F$901,Cleaned_Data!K$2:K$901,9) -> 4669817 | C12: =SUMIFS(Cleaned_Data!G$2:G$901,Cleaned_Data!K$2:K$901,9) -> 651512.66 | D12: =COUNTIFS(Cleaned_Data!K$2:K$901,9) -> 61
A13: Oct | B13: =SUMIFS(Cleaned_Data!F$2:F$901,Cleaned_Data!K$2:K$901,10) -> 6209709 | C13: =SUMIFS(Cleaned_Data!G$2:G$901,Cleaned_Data!K$2:K$901,10) -> 961829.9 | D13: =COUNTIFS(Cleaned_Data!K$2:K$901,10) -> 101
A14: Nov | B14: =SUMIFS(Cleaned_Data!F$2:F$901,Cleaned_Data!K$2:K$901,11) -> 4734019 | C14: =SUMIFS(Cleaned_Data!G$2:G$901,Cleaned_Data!K$2:K$901,11) -> 714144.63 | D14: =COUNTIFS(Cleaned_Data!K$2:K$901,11) -> 85
A15: Dec | B15: =SUMIFS(Cleaned_Data!F$2:F$901,Cleaned_Data!K$2:K$901,12) -> 4425986 | C15: =SUMIFS(Cleaned_Data!G$2:G$901,Cleaned_Data!K$2:K$901,12) -> 659715.46 | D15: =COUNTIFS(Cleaned_Data!K$2:K$901,12) -> 86
